Workbook
Name UPDATE: 'Data Sheet'!$E$1
Name UPDATE: #REF!

Sheet HistoricalFS
B2: ="Historical Financial Data - "&'Data Sheet'!B1 -> Historical Financial Data - ADANI ENTERPRISES LTD
B3: Year | C3: ='Data Sheet'!B16 -> 42825 | D3: ='Data Sheet'!C16 -> 43190 | E3: ='Data Sheet'!D16 -> 43555 | F3: ='Data Sheet'!E16 -> 43921 | G3: ='Data Sheet'!F16 -> 44286 | H3: ='Data Sheet'!G16 -> 44651 | I3: ='Data Sheet'!H16 -> 45016 | J3: ='Data Sheet'!I16 -> 45382 | ... L3: ='Data Sheet'!K16 -> 46112 | M3: TTM
A5: # | B5: ="Income Statement" -> Income Statement
B6: Sales | C6: =IFERROR('Data Sheet'!B17,0) -> 36532.86 | D6: =IFERROR('Data Sheet'!C17,0) -> 35923.92 | E6: =IFERROR('Data Sheet'!D17,0) -> 40378.66 | F6: =IFERROR('Data Sheet'!E17,0) -> 43402.56 | G6: =IFERROR('Data Sheet'!F17,0) -> 39537.13 | H6: =IFERROR('Data Sheet'!G17,0) -> 69420.18 | I6: =IFERROR('Data Sheet'!H17,0) -> 127539.5 | J6: =IFERROR('Data Sheet'!I17,0) -> 96420.98 | ... L6: =IFERROR('Data Sheet'!K17,0) -> 100468.61 | M6: =IFERROR(SUM('Data Sheet'!H42:K42),0) -> 111431.39
B7: Sales Growth | C7: 0 | D7: =D6/C6-1 -> -0.016668282 | E7: =E6/D6-1 -> 0.12400484 | F7: =F6/E6-1 -> 0.074888567 | G7: =G6/F6-1 -> -0.089059954 | H7: =H6/G6-1 -> 0.75582244 | I7: =I6/H6-1 -> 0.83721074 | J7: =J6/I6-1 -> -0.24399123 | K7: =K6/J6-1 -> 0.015284744 | ... M7: =M6/L6-1 -> 0.10911647
B9: COGS | C9: =IFERROR(SUM('Data Sheet'!B18,'Data Sheet'!B20:B22)-1*'Data Sheet'!B19,0) -> 33410.81 | D9: =IFERROR(SUM('Data Sheet'!C18,'Data Sheet'!C20:C22)-1*'Data Sheet'!C19,0) -> 32775.11 | E9: =IFERROR(SUM('Data Sheet'!D18,'Data Sheet'!D20:D22)-1*'Data Sheet'!D19,0) -> 36535.61 | F9: =IFERROR(SUM('Data Sheet'!E18,'Data Sheet'!E20:E22)-1*'Data Sheet'!E19,0) -> 38471.08 | G9: =IFERROR(SUM('Data Sheet'!F18,'Data Sheet'!F20:F22)-1*'Data Sheet'!F19,0) -> 35449.46 | H9: =IFERROR(SUM('Data Sheet'!G18,'Data Sheet'!G20:G22)-1*'Data Sheet'!G19,0) -> 62752.15 | I9: =IFERROR(SUM('Data Sheet'!H18,'Data Sheet'!H20:H22)-1*'Data Sheet'!H19,0) -> 109762.22 | J9: =IFERROR(SUM('Data Sheet'!I18,'Data Sheet'!I20:I22)-1*'Data Sheet'!I19,0) -> 75543.69 | ... L9: =IFERROR(SUM('Data Sheet'!K18,'Data Sheet'!K20:K22)-1*'Data Sheet'!K19,0) -> 75523.2 | M9: =IFERROR(SUM('Data Sheet'!H43:K43),0) -> 95733.27
B10: COGS % Sales | C10: =C9/C6 -> 0.91454132 | D10: =D9/D6 -> 0.91234782 | E10: =E9/E6 -> 0.90482473 | F10: =F9/F6 -> 0.88637813 | G10: =G9/G6 -> 0.89661187 | H10: =H9/H6 -> 0.90394681 | I10: =I9/I6 -> 0.86061354 | J10: =J9/J6 -> 0.78347772 | ... M10: =M9/M6 -> 0.859123
B12: Gross Margin | C12: =C6-C9 -> 3122.05 | D12: =D6-D9 -> 3148.81 | E12: =E6-E9 -> 3843.05 | F12: =F6-F9 -> 4931.48 | G12: =G6-G9 -> 4087.67 | H12: =H6-H9 -> 6668.03 | I12: =I6-I9 -> 17777.28 | J12: =J6-J9 -> 20877.29 | ... M12: =M6-M9 -> 15698.12
B13: Gross Margin % Sales | C13: =C12/C6 -> 0.08545868 | D13: =D12/D6 -> 0.087652183 | E13: =E12/E6 -> 0.095175273 | F13: =F12/F6 -> 0.11362187 | G13: =G12/G6 -> 0.10338813 | H13: =H12/H6 -> 0.096053194 | I13: =I12/I6 -> 0.13938646 | J13: =J12/J6 -> 0.21652228 | ... M13: =M12/M6 -> 0.140877
B15: Selling & General Expenses | C15: =IFERROR(SUM('Data Sheet'!B23:B24),0) -> 1219.82 | D15: =IFERROR(SUM('Data Sheet'!C23:C24),0) -> 1111.1 | E15: =IFERROR(SUM('Data Sheet'!D23:D24),0) -> 1873.71 | F15: =IFERROR(SUM('Data Sheet'!E23:E24),0) -> 2637.09 | G15: =IFERROR(SUM('Data Sheet'!F23:F24),0) -> 1582.02 | H15: =IFERROR(SUM('Data Sheet'!G23:G24),0) -> 2954.43 | I15: =IFERROR(SUM('Data Sheet'!H23:H24),0) -> 8959.59 | J15: =IFERROR(SUM('Data Sheet'!I23:I24),0) -> 9500.69 | ... M15: =IFERROR(SUM('Data Sheet'!L23:L24),0) -> 0
B16: S&G Exp % Sales | C16: =C15/C6 -> 0.033389666 | D16: =D15/D6 -> 0.030929253 | E16: =E15/E6 -> 0.046403472 | F16: =F15/F6 -> 0.060758858 | G16: =G15/G6 -> 0.040013527 | H16: =H15/H6 -> 0.042558662 | I16: =I15/I6 -> 0.070249531 | J16: =J15/J6 -> 0.098533431 | ... L16: =L15/L6 -> 0.10903535
B18: EBITDA | C18: =C12-C15 -> 1902.23 | D18: =D12-D15 -> 2037.71 | E18: =E12-E15 -> 1969.34 | F18: =F12-F15 -> 2294.39 | G18: =G12-G15 -> 2505.65 | H18: =H12-H15 -> 3713.6 | I18: =I12-I15 -> 8817.69 | J18: =J12-J15 -> 11376.6 | ... L18: =L12-L15 -> 13990.78 | M18: =IFERROR(SUM('Data Sheet'!H42:K42)-SUM('Data Sheet'!H43:K43),0) -> 15698.12
B19: EBITDA Margins | C19: =C18/C6 -> 0.052069014 | D19: =D18/D6 -> 0.05672293 | E19: =E18/E6 -> 0.048771802 | F19: =F18/F6 -> 0.052863011 | G19: =G18/G6 -> 0.063374605 | H19: =H18/H6 -> 0.053494531 | I19: =I18/I6 -> 0.069136934 | J19: =J18/J6 -> 0.11798884 | ... M19: =M18/M6 -> 0.140877
B21: Depreciation | C21: =IFERROR('Data Sheet'!B26,0) -> 315.46 | D21: =IFERROR('Data Sheet'!C26,0) -> 663.92 | E21: =IFERROR('Data Sheet'!D26,0) -> 389.77 | F21: =IFERROR('Data Sheet'!E26,0) -> 472.06 | G21: =IFERROR('Data Sheet'!F26,0) -> 537.14 | H21: =IFERROR('Data Sheet'!G26,0) -> 1247.78 | I21: =IFERROR('Data Sheet'!H26,0) -> 2436.14 | J21: =IFERROR('Data Sheet'!I26,0) -> 3042.15 | ... L21: =IFERROR('Data Sheet'!K26,0) -> 6135.34 | M21: =IFERROR(SUM('Data Sheet'!H45:K45),0) -> 6777.39
B22: Depreciation%Sales | C22: =C21/C6 -> 0.0086349659 | D22: =D21/D6 -> 0.018481279 | E22: =E21/E6 -> 0.0096528711 | F22: =F21/F6 -> 0.010876317 | G22: =G21/G6 -> 0.01358571 | H22: =H21/H6 -> 0.017974312 | I22: =I21/I6 -> 0.019101063 | J22: =J21/J6 -> 0.031550706 | ... M22: =M21/M6 -> 0.060821192
B24: EBIT (OPM) | C24: =C18-C21 -> 1586.77 | D24: =D18-D21 -> 1373.79 | E24: =E18-E21 -> 1579.57 | F24: =F18-F21 -> 1822.33 | G24: =G18-G21 -> 1968.51 | H24: =H18-H21 -> 2465.82 | I24: =I18-I21 -> 6381.55 | J24: =J18-J21 -> 8334.45 | ... M24: =M18-M21 -> 8920.73
B25: EBIT Margins | C25: =C24/C6 -> 0.043434048 | D25: =D24/D6 -> 0.038241651 | E25: =E24/E6 -> 0.039118931 | F25: =F24/F6 -> 0.041986694 | G25: =G24/G6 -> 0.049788895 | H25: =H24/H6 -> 0.035520219 | I25: =I24/I6 -> 0.050035871 | J25: =J24/J6 -> 0.086438138 | ... M25: =M24/M6 -> 0.080055808
B27: Other Income | C27: =IFERROR('Data Sheet'!B25,0) -> 749.41 | D27: =IFERROR('Data Sheet'!C25,0) -> 363.21 | E27: =IFERROR('Data Sheet'!D25,0) -> 504.22 | F27: =IFERROR('Data Sheet'!E25,0) -> 872.32 | G27: =IFERROR('Data Sheet'!F25,0) -> 494.31 | H27: =IFERROR('Data Sheet'!G25,0) -> 1012.11 | I27: =IFERROR('Data Sheet'!H25,0) -> 834.23 | J27: =IFERROR('Data Sheet'!I25,0) -> 1146.39 | ... L27: =IFERROR('Data Sheet'!K25,0) -> 11688.34 | M27: =IFERROR(SUM('Data Sheet'!H44:K44),0) -> 9192.84
B28: Other income % Sales | C28: =C27/C6 -> 0.020513313 | D28: =D27/D6 -> 0.010110534 | E28: =E27/E6 -> 0.012487289 | F28: =F27/F6 -> 0.020098354 | G28: =G27/G6 -> 0.012502425 | H28: =H27/H6 -> 0.014579478 | I28: =I27/I6 -> 0.006540954 | J28: =J27/J6 -> 0.011889425 | ... M28: =M27/M6 -> 0.082497759
B30: Interest | C30: =IFERROR('Data Sheet'!B27,0) -> 1257.31 | D30: =IFERROR('Data Sheet'!C27,0) -> 1250.17 | E30: =IFERROR('Data Sheet'!D27,0) -> 1625.07 | F30: =IFERROR('Data Sheet'!E27,0) -> 1572.32 | G30: =IFERROR('Data Sheet'!F27,0) -> 1376.85 | H30: =IFERROR('Data Sheet'!G27,0) -> 2525.88 | I30: =IFERROR('Data Sheet'!H27,0) -> 3968.9 | J30: =IFERROR('Data Sheet'!I27,0) -> 4554.7 | ... L30: =IFERROR('Data Sheet'!K27,0) -> 6019.12 | M30: =IFERROR(SUM('Data Sheet'!H46:K46),0) -> 7404.57
B31: Interest % Sales | C31: =C30/C6 -> 0.034415866 | D31: =D30/D6 -> 0.034800489 | E31: =E30/E6 -> 0.040245763 | F31: =F30/F6 -> 0.036226435 | G31: =G30/G6 -> 0.034824227 | H31: =H30/H6 -> 0.036385385 | I31: =I30/I6 -> 0.031118987 | J31: =J30/J6 -> 0.047237645 | ... M31: =M30/M6 -> 0.066449588
B33: Earnings Before Tax | C33: =IFERROR(SUM(C24,C27)-C30,0) -> 1078.87 | D33: =IFERROR(SUM(D24,D27)-D30,0) -> 486.83 | E33: =IFERROR(SUM(E24,E27)-E30,0) -> 458.72 | F33: =IFERROR(SUM(F24,F27)-F30,0) -> 1122.33 | G33: =IFERROR(SUM(G24,G27)-G30,0) -> 1085.97 | H33: =IFERROR(SUM(H24,H27)-H30,0) -> 952.05 | I33: =IFERROR(SUM(I24,I27)-I30,0) -> 3246.88 | J33: =IFERROR(SUM(J24,J27)-J30,0) -> 4926.14 | ... M33: =IFERROR(SUM(M24,M27)-M30,0) -> 10709
B34: EBT % Sales | C34: =C33/C6 -> 0.029531496 | D34: =D33/D6 -> 0.013551695 | E34: =E33/E6 -> 0.011360456 | F34: =F33/F6 -> 0.025858613 | G34: =G33/G6 -> 0.027467092 | H34: =H33/H6 -> 0.013714312 | I34: =I33/I6 -> 0.025457839 | J34: =J33/J6 -> 0.051089918 | ... M34: =M33/M6 -> 0.096103979
B36: Tax | C36: =IFERROR('Data Sheet'!B29,0) -> 271.15 | D36: =IFERROR('Data Sheet'!C29,0) -> 112.11 | E36: =IFERROR('Data Sheet'!D29,0) -> 144.54 | F36: =IFERROR('Data Sheet'!E29,0) -> 324.33 | G36: =IFERROR('Data Sheet'!F29,0) -> 339.65 | H36: =IFERROR('Data Sheet'!G29,0) -> 476.68 | I36: =IFERROR('Data Sheet'!H29,0) -> 1037.94 | J36: =IFERROR('Data Sheet'!I29,0) -> 1631.51 | ... L36: =IFERROR('Data Sheet'!K29,0) -> 3831.15 | M36: =IFERROR(SUM('Data Sheet'!H48:K48),0) -> 3478.94
B37: Effective Tax Rate | C37: =C36/C33 -> 0.25132778 | D37: =D36/D33 -> 0.23028573 | E37: =E36/E33 -> 0.31509418 | F37: =F36/F33 -> 0.28897918 | G37: =G36/G33 -> 0.31276186 | H37: =H36/H33 -> 0.50068799 | I37: =I36/I33 -> 0.31967304 | J37: =J36/J33 -> 0.3311944 | ... M37: =M36/M33 -> 0.32486133
B39: Net Profit | C39: =C33-C36 -> 807.72 | D39: =D33-D36 -> 374.72 | E39: =E33-E36 -> 314.18 | F39: =F33-F36 -> 798 | G39: =G33-G36 -> 746.32 | H39: =H33-H36 -> 475.37 | I39: =I33-I36 -> 2208.94 | J39: =J33-J36 -> 3294.63 | ... M39: =M33-M36 -> 7230.06
B40: Net Margins | C40: =C39/C6 -> 0.022109411 | D40: =D39/D6 -> 0.010430933 | E40: =E39/E6 -> 0.0077808427 | F40: =F39/F6 -> 0.018386012 | G40: =G39/G6 -> 0.018876433 | H40: =H39/H6 -> 0.0068477206 | I40: =I39/I6 -> 0.017319654 | J40: =J39/J6 -> 0.034169223 | ... M40: =M39/M6 -> 0.064883513
B42: No of Equity Shares | C42: =IFERROR('Data Sheet'!B93,0) -> 123.18 | D42: =IFERROR('Data Sheet'!C93,0) -> 123.18 | E42: =IFERROR('Data Sheet'!D93,0) -> 123.18 | F42: =IFERROR('Data Sheet'!E93,0) -> 123.18 | G42: =IFERROR('Data Sheet'!F93,0) -> 123.18 | H42: =IFERROR('Data Sheet'!G93,0) -> 123.18 | I42: =IFERROR('Data Sheet'!H93,0) -> 127.68 | J42: =IFERROR('Data Sheet'!I93,0) -> 127.68 | ... L42: =IFERROR('Data Sheet'!K93,0) -> 129.16
B44: Earnings per Share | C44: =IFERROR(C39/C42,0) -> 6.5572333 | D44: =IFERROR(D39/D42,0) -> 3.0420523 | E44: =IFERROR(E39/E42,0) -> 2.5505764 | F44: =IFERROR(F39/F42,0) -> 6.4783244 | G44: =IFERROR(G39/G42,0) -> 6.0587758 | H44: =IFERROR(H39/H42,0) -> 3.8591492 | I44: =IFERROR(I39/I42,0) -> 17.300595 | J44: =IFERROR(J39/J42,0) -> 25.803806 | ... L44: =IFERROR(L39/L42,0) -> 75.050403
B45: EPS Growth % | C45: 0 | D45: =D44/C44-1 -> -0.53607686 | E45: =E44/D44-1 -> -0.16156063 | F45: =F44/E44-1 -> 1.5399453 | G45: =G44/F44-1 -> -0.064761905 | H45: =H44/G44-1 -> -0.36304802 | I45: =I44/H44-1 -> 3.4830076 | J45: =J44/I44-1 -> 0.49149818 | K45: =K44/J44-1 -> 1.2476105 | L45: =L44/K44-1 -> 0.2940415
B47: Dividend per Share | C47: =IFERROR('Data Sheet'!B31/C42,0) -> 0.35711966 | D47: =IFERROR('Data Sheet'!C31/D42,0) -> 0.35711966 | E47: =IFERROR('Data Sheet'!D31/E42,0) -> 0.35711966 | F47: =IFERROR('Data Sheet'!E31/F42,0) -> 0.89283975 | G47: =IFERROR('Data Sheet'!F31/G42,0) -> 0.89283975 | H47: =IFERROR('Data Sheet'!G31/H42,0) -> 0.89283975 | I47: =IFERROR('Data Sheet'!H31/I42,0) -> 1.0714286 | J47: =IFERROR('Data Sheet'!I31/J42,0) -> 1.1607143 | ... L47: =IFERROR('Data Sheet'!K31/L42,0) -> 1.3007897
B48: Dividend payout ratio | C48: =IFERROR(C47/C44,0) -> 0.054461942 | D48: =IFERROR(D47/D44,0) -> 0.11739432 | E48: =IFERROR(E47/E44,0) -> 0.14001528 | F48: =IFERROR(F47/F44,0) -> 0.13781955 | G48: =IFERROR(G47/G44,0) -> 0.14736306 | H48: =IFERROR(H47/H44,0) -> 0.23135663 | I48: =IFERROR(I47/I44,0) -> 0.061930157 | J48: =IFERROR(J47/J44,0) -> 0.044982289 | ... L48: =IFERROR(L47/L44,0) -> 0.017332215
B50: Retained Earnings | C50: =IFERROR(IF(C44>C47,1-C48,0),0) -> 0.94553806 | D50: =IFERROR(IF(D44>D47,1-D48,0),0) -> 0.88260568 | E50: =IFERROR(IF(E44>E47,1-E48,0),0) -> 0.85998472 | F50: =IFERROR(IF(F44>F47,1-F48,0),0) -> 0.86218045 | G50: =IFERROR(IF(G44>G47,1-G48,0),0) -> 0.85263694 | H50: =IFERROR(IF(H44>H47,1-H48,0),0) -> 0.76864337 | I50: =IFERROR(IF(I44>I47,1-I48,0),0) -> 0.93806984 | J50: =IFERROR(IF(J44>J47,1-J48,0),0) -> 0.95501771 | ... L50: =IFERROR(IF(L44>L47,1-L48,0),0) -> 0.98266778
A52: # | B52: ="Balance Sheet" -> Balance Sheet
B53: Equity Share Capital | C53: =IFERROR('Data Sheet'!B57,0) -> 109.98 | D53: =IFERROR('Data Sheet'!C57,0) -> 109.98 | E53: =IFERROR('Data Sheet'!D57,0) -> 109.98 | F53: =IFERROR('Data Sheet'!E57,0) -> 109.98 | G53: =IFERROR('Data Sheet'!F57,0) -> 109.98 | H53: =IFERROR('Data Sheet'!G57,0) -> 109.98 | I53: =IFERROR('Data Sheet'!H57,0) -> 114 | J53: =IFERROR('Data Sheet'!I57,0) -> 114 | ... L53: =IFERROR('Data Sheet'!K57,0) -> 129.24
B54: Reserves | C54: =IFERROR('Data Sheet'!B58,0) -> 14025.99 | D54: =IFERROR('Data Sheet'!C58,0) -> 14979.19 | E54: =IFERROR('Data Sheet'!D58,0) -> 14645.96 | F54: =IFERROR('Data Sheet'!E58,0) -> 16836.59 | G54: =IFERROR('Data Sheet'!F58,0) -> 17048.59 | H54: =IFERROR('Data Sheet'!G58,0) -> 22146.53 | I54: =IFERROR('Data Sheet'!H58,0) -> 32937.01 | J54: =IFERROR('Data Sheet'!I58,0) -> 38962.09 | ... L54: =IFERROR('Data Sheet'!K58,0) -> 80796.71
B55: Borrowings | C55: =IFERROR('Data Sheet'!B59,0) -> 20845.72 | D55: =IFERROR('Data Sheet'!C59,0) -> 17636.69 | E55: =IFERROR('Data Sheet'!D59,0) -> 11243.2 | F55: =IFERROR('Data Sheet'!E59,0) -> 12419.3 | G55: =IFERROR('Data Sheet'!F59,0) -> 16227.06 | H55: =IFERROR('Data Sheet'!G59,0) -> 41604.03 | I55: =IFERROR('Data Sheet'!H59,0) -> 53200.46 | J55: =IFERROR('Data Sheet'!I59,0) -> 65310.15 | ... L55: =IFERROR('Data Sheet'!K59,0) -> 106621.79
B56: Other Liabilities | C56: =IFERROR('Data Sheet'!B60,0) -> 12629.78 | D56: =IFERROR('Data Sheet'!C60,0) -> 23679.48 | E56: =IFERROR('Data Sheet'!D60,0) -> 16537.04 | F56: =IFERROR('Data Sheet'!E60,0) -> 17509.19 | G56: =IFERROR('Data Sheet'!F60,0) -> 18231.09 | H56: =IFERROR('Data Sheet'!G60,0) -> 37725.82 | I56: =IFERROR('Data Sheet'!H60,0) -> 55027.01 | J56: =IFERROR('Data Sheet'!I60,0) -> 56200 | ... L56: =IFERROR('Data Sheet'!K60,0) -> 73320.64
B57: Total Liabilities | C57: =IFERROR(SUM(C53:C56),0) -> 47611.47 | D57: =IFERROR(SUM(D53:D56),0) -> 56405.34 | E57: =IFERROR(SUM(E53:E56),0) -> 42536.18 | F57: =IFERROR(SUM(F53:F56),0) -> 46875.06 | G57: =IFERROR(SUM(G53:G56),0) -> 51616.72 | H57: =IFERROR(SUM(H53:H56),0) -> 101586.36 | I57: =IFERROR(SUM(I53:I56),0) -> 141278.48 | J57: =IFERROR(SUM(J53:J56),0) -> 160586.24 | ... L57: =IFERROR(SUM(L53:L56),0) -> 260868.38
B59: Net Block | C59: =IFERROR('Data Sheet'!B62,0) -> 13667.98 | D59: =IFERROR('Data Sheet'!C62,0) -> 10555.19 | E59: =IFERROR('Data Sheet'!D62,0) -> 9020.11 | F59: =IFERROR('Data Sheet'!E62,0) -> 10476.46 | G59: =IFERROR('Data Sheet'!F62,0) -> 10837.61 | H59: =IFERROR('Data Sheet'!G62,0) -> 30122.77 | I59: =IFERROR('Data Sheet'!H62,0) -> 56881.13 | J59: =IFERROR('Data Sheet'!I62,0) -> 65978.3 | ... L59: =IFERROR('Data Sheet'!K62,0) -> 115173.81
...

Sheet Ratio Analysis
B2: ="Historical Financial Data - "&'Data Sheet'!B1 -> Historical Financial Data - ADANI ENTERPRISES LTD
B3: Year | C3: ='Data Sheet'!B16 -> 42825 | D3: ='Data Sheet'!C16 -> 43190 | E3: ='Data Sheet'!D16 -> 43555 | F3: ='Data Sheet'!E16 -> 43921 | G3: ='Data Sheet'!F16 -> 44286 | H3: ='Data Sheet'!G16 -> 44651 | I3: ='Data Sheet'!H16 -> 45016 | J3: ='Data Sheet'!I16 -> 45382 | ... L3: ='Data Sheet'!K16 -> 46112 | M3: TREND | N3: Mean | O3: Median
A4: # | B4: GROWTH RATIOS
B5: Sales Growth | D5: =IFERROR(HistoricalFS!D7,0) -> -0.016668282 | E5: =IFERROR(HistoricalFS!E7,0) -> 0.12400484 | F5: =IFERROR(HistoricalFS!F7,0) -> 0.074888567 | G5: =IFERROR(HistoricalFS!G7,0) -> -0.089059954 | H5: =IFERROR(HistoricalFS!H7,0) -> 0.75582244 | I5: =IFERROR(HistoricalFS!I7,0) -> 0.83721074 | J5: =IFERROR(HistoricalFS!J7,0) -> -0.24399123 | K5: =IFERROR(HistoricalFS!K7,0) -> 0.015284744 | L5: =IFERROR(HistoricalFS!L7,0) -> 0.026292115 | N5: =IFERROR(AVERAGE(C5:L5),0) -> 0.16486489 | O5: =IFERROR(MEDIAN(C5:L5),0) -> 0.026292115
B6: EBITDA Growth | D6: =IFERROR(HistoricalFS!D18/HistoricalFS!C18-1,0) -> 0.071221671 | E6: =IFERROR(HistoricalFS!E18/HistoricalFS!D18-1,0) -> -0.03355237 | F6: =IFERROR(HistoricalFS!F18/HistoricalFS!E18-1,0) -> 0.1650553 | G6: =IFERROR(HistoricalFS!G18/HistoricalFS!F18-1,0) -> 0.092076761 | H6: =IFERROR(HistoricalFS!H18/HistoricalFS!G18-1,0) -> 0.48209048 | I6: =IFERROR(HistoricalFS!I18/HistoricalFS!H18-1,0) -> 1.3744318 | J6: =IFERROR(HistoricalFS!J18/HistoricalFS!I18-1,0) -> 0.29020186 | K6: =IFERROR(HistoricalFS!K18/HistoricalFS!J18-1,0) -> 0.2527495 | L6: =IFERROR(HistoricalFS!L18/HistoricalFS!K18-1,0) -> -0.018330722 | N6: =IFERROR(AVERAGE(C6:L6),0) -> 0.29732714 | O6: =IFERROR(MEDIAN(C6:L6),0) -> 0.1650553
B7: EBIT Growth | D7: =IFERROR(HistoricalFS!D24/HistoricalFS!C24-1,0) -> -0.13422235 | E7: =IFERROR(HistoricalFS!E24/HistoricalFS!D24-1,0) -> 0.14979 | F7: =IFERROR(HistoricalFS!F24/HistoricalFS!E24-1,0) -> 0.1536874 | G7: =IFERROR(HistoricalFS!G24/HistoricalFS!F24-1,0) -> 0.080215987 | H7: =IFERROR(HistoricalFS!H24/HistoricalFS!G24-1,0) -> 0.2526327 | I7: =IFERROR(HistoricalFS!I24/HistoricalFS!H24-1,0) -> 1.5880032 | J7: =IFERROR(HistoricalFS!J24/HistoricalFS!I24-1,0) -> 0.30602283 | K7: =IFERROR(HistoricalFS!K24/HistoricalFS!J24-1,0) -> 0.20472257 | L7: =IFERROR(HistoricalFS!L24/HistoricalFS!K24-1,0) -> -0.2176402 | N7: =IFERROR(AVERAGE(C7:L7),0) -> 0.26480134 | O7: =IFERROR(MEDIAN(C7:L7),0) -> 0.1536874
B8: Net Profit Growth | D8: =IFERROR(HistoricalFS!D39/HistoricalFS!C39-1,0) -> -0.53607686 | E8: =IFERROR(HistoricalFS!E39/HistoricalFS!D39-1,0) -> -0.16156063 | F8: =IFERROR(HistoricalFS!F39/HistoricalFS!E39-1,0) -> 1.5399453 | G8: =IFERROR(HistoricalFS!G39/HistoricalFS!F39-1,0) -> -0.064761905 | H8: =IFERROR(HistoricalFS!H39/HistoricalFS!G39-1,0) -> -0.36304802 | I8: =IFERROR(HistoricalFS!I39/HistoricalFS!H39-1,0) -> 3.6467804 | J8: =IFERROR(HistoricalFS!J39/HistoricalFS!I39-1,0) -> 0.49149818 | K8: =IFERROR(HistoricalFS!K39/HistoricalFS!J39-1,0) -> 1.2756 | L8: =IFERROR(HistoricalFS!L39/HistoricalFS!K39-1,0) -> 0.29294035 | N8: =IFERROR(AVERAGE(C8:L8),0) -> 0.68014631 | O8: =IFERROR(MEDIAN(C8:L8),0) -> 0.29294035
B9: EPS Growth | D9: =IFERROR(HistoricalFS!D45,0) -> -0.53607686 | E9: =IFERROR(HistoricalFS!E45,0) -> -0.16156063 | F9: =IFERROR(HistoricalFS!F45,0) -> 1.5399453 | G9: =IFERROR(HistoricalFS!G45,0) -> -0.064761905 | H9: =IFERROR(HistoricalFS!H45,0) -> -0.36304802 | I9: =IFERROR(HistoricalFS!I45,0) -> 3.4830076 | J9: =IFERROR(HistoricalFS!J45,0) -> 0.49149818 | K9: =IFERROR(HistoricalFS!K45,0) -> 1.2476105 | L9: =IFERROR(HistoricalFS!L45,0) -> 0.2940415 | N9: =IFERROR(AVERAGE(C9:L9),0) -> 0.65896173 | O9: =IFERROR(MEDIAN(C9:L9),0) -> 0.2940415
B10: Dividend per Share Growth | D10: =IFERROR(HistoricalFS!D47/HistoricalFS!C47-1,0) -> 0 | E10: =IFERROR(HistoricalFS!E47/HistoricalFS!D47-1,0) -> 0 | F10: =IFERROR(HistoricalFS!F47/HistoricalFS!E47-1,0) -> 1.5001137 | G10: =IFERROR(HistoricalFS!G47/HistoricalFS!F47-1,0) -> 0 | H10: =IFERROR(HistoricalFS!H47/HistoricalFS!G47-1,0) -> 0 | I10: =IFERROR(HistoricalFS!I47/HistoricalFS!H47-1,0) -> 0.20002338 | J10: =IFERROR(HistoricalFS!J47/HistoricalFS!I47-1,0) -> 0.083333333 | K10: =IFERROR(HistoricalFS!K47/HistoricalFS!J47-1,0) -> 2.9752873e-05 | L10: =IFERROR(HistoricalFS!L47/HistoricalFS!K47-1,0) -> 0.12064703 | N10: =IFERROR(AVERAGE(C10:L10),0) -> 0.21157191 | O10: =IFERROR(MEDIAN(C10:L10),0) -> 2.9752873e-05
A12: # | B12: PROFITABILITY & MARGIN RATIOS
B13: Gross Margin | C13: =IFERROR(HistoricalFS!C13,0) -> 0.08545868 | D13: =IFERROR(HistoricalFS!D13,0) -> 0.087652183 | E13: =IFERROR(HistoricalFS!E13,0) -> 0.095175273 | F13: =IFERROR(HistoricalFS!F13,0) -> 0.11362187 | G13: =IFERROR(HistoricalFS!G13,0) -> 0.10338813 | H13: =IFERROR(HistoricalFS!H13,0) -> 0.096053194 | I13: =IFERROR(HistoricalFS!I13,0) -> 0.13938646 | J13: =IFERROR(HistoricalFS!J13,0) -> 0.21652228 | ... L13: =IFERROR(HistoricalFS!L13,0) -> 0.24829059 | N13: =IFERROR(AVERAGE(C13:L13),0) -> 0.14348128 | O13: =IFERROR(MEDIAN(C13:L13),0) -> 0.108505
B14: EBITDA Margin | C14: =IFERROR(HistoricalFS!C19,0) -> 0.052069014 | D14: =IFERROR(HistoricalFS!D19,0) -> 0.05672293 | E14: =IFERROR(HistoricalFS!E19,0) -> 0.048771802 | F14: =IFERROR(HistoricalFS!F19,0) -> 0.052863011 | G14: =IFERROR(HistoricalFS!G19,0) -> 0.063374605 | H14: =IFERROR(HistoricalFS!H19,0) -> 0.053494531 | I14: =IFERROR(HistoricalFS!I19,0) -> 0.069136934 | J14: =IFERROR(HistoricalFS!J19,0) -> 0.11798884 | ... L14: =IFERROR(HistoricalFS!L19,0) -> 0.13925524 | N14: =IFERROR(AVERAGE(C14:L14),0) -> 0.079926214 | O14: =IFERROR(MEDIAN(C14:L14),0) -> 0.060048768
B15: EBIT Margin | C15: =IFERROR(HistoricalFS!C25,0) -> 0.043434048 | D15: =IFERROR(HistoricalFS!D25,0) -> 0.038241651 | E15: =IFERROR(HistoricalFS!E25,0) -> 0.039118931 | F15: =IFERROR(HistoricalFS!F25,0) -> 0.041986694 | G15: =IFERROR(HistoricalFS!G25,0) -> 0.049788895 | H15: =IFERROR(HistoricalFS!H25,0) -> 0.035520219 | I15: =IFERROR(HistoricalFS!I25,0) -> 0.050035871 | J15: =IFERROR(HistoricalFS!J25,0) -> 0.086438138 | ... L15: =IFERROR(HistoricalFS!L25,0) -> 0.078188003 | N15: =IFERROR(AVERAGE(C15:L15),0) -> 0.056531873 | O15: =IFERROR(MEDIAN(C15:L15),0) -> 0.046611471
B16: EBT Margin | C16: =IFERROR(HistoricalFS!C34,0) -> 0.029531496 | D16: =IFERROR(HistoricalFS!D34,0) -> 0.013551695 | E16: =IFERROR(HistoricalFS!E34,0) -> 0.011360456 | F16: =IFERROR(HistoricalFS!F34,0) -> 0.025858613 | G16: =IFERROR(HistoricalFS!G34,0) -> 0.027467092 | H16: =IFERROR(HistoricalFS!H34,0) -> 0.013714312 | I16: =IFERROR(HistoricalFS!I34,0) -> 0.025457839 | J16: =IFERROR(HistoricalFS!J34,0) -> 0.051089918 | ... L16: =IFERROR(HistoricalFS!L34,0) -> 0.13461578 | N16: =IFERROR(AVERAGE(C16:L16),0) -> 0.043955569 | O16: =IFERROR(MEDIAN(C16:L16),0) -> 0.026662853
B17: Net Profit Margin | C17: =IFERROR(HistoricalFS!C40,0) -> 0.022109411 | D17: =IFERROR(HistoricalFS!D40,0) -> 0.010430933 | E17: =IFERROR(HistoricalFS!E40,0) -> 0.0077808427 | F17: =IFERROR(HistoricalFS!F40,0) -> 0.018386012 | G17: =IFERROR(HistoricalFS!G40,0) -> 0.018876433 | H17: =IFERROR(HistoricalFS!H40,0) -> 0.0068477206 | I17: =IFERROR(HistoricalFS!I40,0) -> 0.017319654 | J17: =IFERROR(HistoricalFS!J40,0) -> 0.034169223 | ... L17: =IFERROR(HistoricalFS!L40,0) -> 0.096482971 | N17: =IFERROR(AVERAGE(C17:L17),0) -> 0.03089881 | O17: =IFERROR(MEDIAN(C17:L17),0) -> 0.018631223
A19: # | B19: COST & PAYOUT RATIOS (% OF SALES)
B20: Selling & General Expenses % Sales | C20: =IFERROR(HistoricalFS!C16,0) -> 0.033389666 | D20: =IFERROR(HistoricalFS!D16,0) -> 0.030929253 | E20: =IFERROR(HistoricalFS!E16,0) -> 0.046403472 | F20: =IFERROR(HistoricalFS!F16,0) -> 0.060758858 | G20: =IFERROR(HistoricalFS!G16,0) -> 0.040013527 | H20: =IFERROR(HistoricalFS!H16,0) -> 0.042558662 | I20: =IFERROR(HistoricalFS!I16,0) -> 0.070249531 | J20: =IFERROR(HistoricalFS!J16,0) -> 0.098533431 | ... L20: =IFERROR(HistoricalFS!L16,0) -> 0.10903535 | N20: =IFERROR(AVERAGE(C20:L20),0) -> 0.063555065 | O20: =IFERROR(MEDIAN(C20:L20),0) -> 0.053581165
B21: Depreciation%Sales | C21: =IFERROR(HistoricalFS!C22,0) -> 0.0086349659 | D21: =IFERROR(HistoricalFS!D22,0) -> 0.018481279 | E21: =IFERROR(HistoricalFS!E22,0) -> 0.0096528711 | F21: =IFERROR(HistoricalFS!F22,0) -> 0.010876317 | G21: =IFERROR(HistoricalFS!G22,0) -> 0.01358571 | H21: =IFERROR(HistoricalFS!H22,0) -> 0.017974312 | I21: =IFERROR(HistoricalFS!I22,0) -> 0.019101063 | J21: =IFERROR(HistoricalFS!J22,0) -> 0.031550706 | ... L21: =IFERROR(HistoricalFS!L22,0) -> 0.061067233 | N21: =IFERROR(AVERAGE(C21:L21),0) -> 0.023394341 | O21: =IFERROR(MEDIAN(C21:L21),0) -> 0.018227796
B22: Interest % Sales | C22: =IFERROR(HistoricalFS!C31,0) -> 0.034415866 | D22: =IFERROR(HistoricalFS!D31,0) -> 0.034800489 | E22: =IFERROR(HistoricalFS!E31,0) -> 0.040245763 | F22: =IFERROR(HistoricalFS!F31,0) -> 0.036226435 | G22: =IFERROR(HistoricalFS!G31,0) -> 0.034824227 | H22: =IFERROR(HistoricalFS!H31,0) -> 0.036385385 | I22: =IFERROR(HistoricalFS!I31,0) -> 0.031118987 | J22: =IFERROR(HistoricalFS!J31,0) -> 0.047237645 | ... L22: =IFERROR(HistoricalFS!L31,0) -> 0.059910454 | N22: =IFERROR(AVERAGE(C22:L22),0) -> 0.041623104 | O22: =IFERROR(MEDIAN(C22:L22),0) -> 0.03630591
B23: Tax Payout % | C23: =IFERROR(HistoricalFS!C37,0) -> 0.25132778 | D23: =IFERROR(HistoricalFS!D37,0) -> 0.23028573 | E23: =IFERROR(HistoricalFS!E37,0) -> 0.31509418 | F23: =IFERROR(HistoricalFS!F37,0) -> 0.28897918 | G23: =IFERROR(HistoricalFS!G37,0) -> 0.31276186 | H23: =IFERROR(HistoricalFS!H37,0) -> 0.50068799 | I23: =IFERROR(HistoricalFS!I37,0) -> 0.31967304 | J23: =IFERROR(HistoricalFS!J37,0) -> 0.3311944 | ... L23: =IFERROR(HistoricalFS!L37,0) -> 0.28327145 | N23: =IFERROR(AVERAGE(C23:L23),0) -> 0.31169162 | O23: =IFERROR(MEDIAN(C23:L23),0) -> 0.30087052
B24: Dividend Payout % | C24: =IFERROR(HistoricalFS!C48,0) -> 0.054461942 | D24: =IFERROR(HistoricalFS!D48,0) -> 0.11739432 | E24: =IFERROR(HistoricalFS!E48,0) -> 0.14001528 | F24: =IFERROR(HistoricalFS!F48,0) -> 0.13781955 | G24: =IFERROR(HistoricalFS!G48,0) -> 0.14736306 | H24: =IFERROR(HistoricalFS!H48,0) -> 0.23135663 | I24: =IFERROR(HistoricalFS!I48,0) -> 0.061930157 | J24: =IFERROR(HistoricalFS!J48,0) -> 0.044982289 | ... L24: =IFERROR(HistoricalFS!L48,0) -> 0.017332215 | N24: =IFERROR(AVERAGE(C24:L24),0) -> 0.097266942 | O24: =IFERROR(MEDIAN(C24:L24),0) -> 0.089662239
B25: Retained Earnings% | C25: =IFERROR(HistoricalFS!C50,0) -> 0.94553806 | D25: =IFERROR(HistoricalFS!D50,0) -> 0.88260568 | E25: =IFERROR(HistoricalFS!E50,0) -> 0.85998472 | F25: =IFERROR(HistoricalFS!F50,0) -> 0.86218045 | G25: =IFERROR(HistoricalFS!G50,0) -> 0.85263694 | H25: =IFERROR(HistoricalFS!H50,0) -> 0.76864337 | I25: =IFERROR(HistoricalFS!I50,0) -> 0.93806984 | J25: =IFERROR(HistoricalFS!J50,0) -> 0.95501771 | ... L25: =IFERROR(HistoricalFS!L50,0) -> 0.98266778 | N25: =IFERROR(AVERAGE(C25:L25),0) -> 0.90273306 | O25: =IFERROR(MEDIAN(C25:L25),0) -> 0.91033776
A27: # | B27: RETURN & VALUE-CREATION RATIOS
B28: Return on Capital Employed (ROCE) % | C28: =IFERROR(HistoricalFS!C24/SUM(HistoricalFS!C53:C55),0) -> 0.045360015 | D28: =IFERROR(HistoricalFS!D24/SUM(HistoricalFS!D53:D55),0) -> 0.041978729 | E28: =IFERROR(HistoricalFS!E24/SUM(HistoricalFS!E53:E55),0) -> 0.060754702 | F28: =IFERROR(HistoricalFS!F24/SUM(HistoricalFS!F53:F55),0) -> 0.062056054 | G28: =IFERROR(HistoricalFS!G24/SUM(HistoricalFS!G53:G55),0) -> 0.058962793 | H28: =IFERROR(HistoricalFS!H24/SUM(HistoricalFS!H53:H55),0) -> 0.038612577 | I28: =IFERROR(HistoricalFS!I24/SUM(HistoricalFS!I53:I55),0) -> 0.073987724 | J28: =IFERROR(HistoricalFS!J24/SUM(HistoricalFS!J53:J55),0) -> 0.07984242 | ... L28: =IFERROR(HistoricalFS!L24/SUM(HistoricalFS!L53:L55),0) -> 0.041885016 | N28: =IFERROR(AVERAGE(C28:L28),0) -> 0.057425562 | O28: =IFERROR(MEDIAN(C28:L28),0) -> 0.059858748
B29: Return on Equity (ROE) % | C29: =IFERROR(HistoricalFS!C39/SUM(HistoricalFS!C53:C54),0) -> 0.05713934 | D29: =IFERROR(HistoricalFS!D39/SUM(HistoricalFS!D53:D54),0) -> 0.024833705 | E29: =IFERROR(HistoricalFS!E39/SUM(HistoricalFS!E53:E54),0) -> 0.021291765 | F29: =IFERROR(HistoricalFS!F39/SUM(HistoricalFS!F53:F54),0) -> 0.047089175 | G29: =IFERROR(HistoricalFS!G39/SUM(HistoricalFS!G53:G54),0) -> 0.043495466 | H29: =IFERROR(HistoricalFS!H39/SUM(HistoricalFS!H53:H54),0) -> 0.021358695 | I29: =IFERROR(HistoricalFS!I39/SUM(HistoricalFS!I53:I54),0) -> 0.066834266 | J29: =IFERROR(HistoricalFS!J39/SUM(HistoricalFS!J53:J54),0) -> 0.084313195 | ... L29: =IFERROR(HistoricalFS!L39/SUM(HistoricalFS!L53:L54),0) -> 0.11978247 | N29: =IFERROR(AVERAGE(C29:L29),0) -> 0.063514758 | O29: =IFERROR(MEDIAN(C29:L29),0) -> 0.052114258
B30: Return on Assets (ROA) % | C30: =IFERROR(HistoricalFS!C39/HistoricalFS!C70,0) -> 0.01696482 | D30: =IFERROR(HistoricalFS!D39/HistoricalFS!D70,0) -> 0.0066433426 | E30: =IFERROR(HistoricalFS!E39/HistoricalFS!E70,0) -> 0.0073861828 | F30: =IFERROR(HistoricalFS!F39/HistoricalFS!F70,0) -> 0.017023978 | G30: =IFERROR(HistoricalFS!G39/HistoricalFS!G70,0) -> 0.014458881 | H30: =IFERROR(HistoricalFS!H39/HistoricalFS!H70,0) -> 0.0046794668 | I30: =IFERROR(HistoricalFS!I39/HistoricalFS!I70,0) -> 0.015635361 | J30: =IFERROR(HistoricalFS!J39/HistoricalFS!J70,0) -> 0.020516266 | ... L30: =IFERROR(HistoricalFS!L39/HistoricalFS!L70,0) -> 0.037158624 | N30: =IFERROR(AVERAGE(C30:L30),0) -> 0.017836194 | O30: =IFERROR(MEDIAN(C30:L30),0) -> 0.01630009
B31: Return on Invested Capital (ROIC) % | C31: =IFERROR(HistoricalFS!C24*(1-HistoricalFS!C37)/(SUM(HistoricalFS!C53:C54)+HistoricalFS!C55),0) -> 0.033959784 | D31: =IFERROR(HistoricalFS!D24*(1-HistoricalFS!D37)/(SUM(HistoricalFS!D53:D54)+HistoricalFS!D55),0) -> 0.032311627 | E31: =IFERROR(HistoricalFS!E24*(1-HistoricalFS!E37)/(SUM(HistoricalFS!E53:E54)+HistoricalFS!E55),0) -> 0.041611249 | F31: =IFERROR(HistoricalFS!F24*(1-HistoricalFS!F37)/(SUM(HistoricalFS!F53:F54)+HistoricalFS!F55),0) -> 0.044123146 | G31: =IFERROR(HistoricalFS!G24*(1-HistoricalFS!G37)/(SUM(HistoricalFS!G53:G54)+HistoricalFS!G55),0) -> 0.04052148 | H31: =IFERROR(HistoricalFS!H24*(1-HistoricalFS!H37)/(SUM(HistoricalFS!H53:H54)+HistoricalFS!H55),0) -> 0.019279723 | I31: =IFERROR(HistoricalFS!I24*(1-HistoricalFS!I37)/(SUM(HistoricalFS!I53:I54)+HistoricalFS!I55),0) -> 0.050335844 | J31: =IFERROR(HistoricalFS!J24*(1-HistoricalFS!J37)/(SUM(HistoricalFS!J53:J54)+HistoricalFS!J55),0) -> 0.053399057 | ... L31: =IFERROR(HistoricalFS!L24*(1-HistoricalFS!L37)/(SUM(HistoricalFS!L53:L54)+HistoricalFS!L55),0) -> 0.030020187 | N31: =IFERROR(AVERAGE(C31:L31),0) -> 0.039629151 | O31: =IFERROR(MEDIAN(C31:L31),0) -> 0.041066365
B32: Self Sustained Growth Rate | C32: =IFERROR(C25*C29,0) -> 0.054027421 | D32: =IFERROR(D25*D29,0) -> 0.021918369 | E32: =IFERROR(E25*E29,0) -> 0.018310592 | F32: =IFERROR(F25*F29,0) -> 0.040599366 | G32: =IFERROR(G25*G29,0) -> 0.037085841 | H32: =IFERROR(H25*H29,0) -> 0.016417219 | I32: =IFERROR(I25*I29,0) -> 0.06269521 | J32: =IFERROR(J25*J29,0) -> 0.080520595 | ... L32: =IFERROR(L25*L29,0) -> 0.11770637 | N32: =IFERROR(AVERAGE(C32:L32),0) -> 0.059530822 | O32: =IFERROR(MEDIAN(C32:L32),0) -> 0.047313393
A34: # | B34: TURNOVER & EFFICIENCY RATIOS (times)
B35: Debtor Turnover Ratio | C35: =IFERROR(HistoricalFS!C6/HistoricalFS!C65,0) -> 2.8671776 | D35: =IFERROR(HistoricalFS!D6/HistoricalFS!D65,0) -> 2.9692208 | E35: =IFERROR(HistoricalFS!E6/HistoricalFS!E65,0) -> 2.8222951 | F35: =IFERROR(HistoricalFS!F6/HistoricalFS!F65,0) -> 3.3014461 | G35: =IFERROR(HistoricalFS!G6/HistoricalFS!G65,0) -> 3.2995314 | H35: =IFERROR(HistoricalFS!H6/HistoricalFS!H65,0) -> 5.0626618 | I35: =IFERROR(HistoricalFS!I6/HistoricalFS!I65,0) -> 10.160178 | J35: =IFERROR(HistoricalFS!J6/HistoricalFS!J65,0) -> 9.8459787 | ... L35: =IFERROR(HistoricalFS!L6/HistoricalFS!L65,0) -> 8.0101837 | N35: =IFERROR(AVERAGE(C35:L35),0) -> 5.8518578 | O35: =IFERROR(MEDIAN(C35:L35),0) -> 4.1820539
B36: Creditor Turnover Ratio | C36: =IFERROR(HistoricalFS!C6/HistoricalFS!C56,0) -> 2.8925967 | D36: =IFERROR(HistoricalFS!D6/HistoricalFS!D56,0) -> 1.5170907 | E36: =IFERROR(HistoricalFS!E6/HistoricalFS!E56,0) -> 2.4417102 | F36: =IFERROR(HistoricalFS!F6/HistoricalFS!F56,0) -> 2.4788445 | G36: =IFERROR(HistoricalFS!G6/HistoricalFS!G56,0) -> 2.1686652 | H36: =IFERROR(HistoricalFS!H6/HistoricalFS!H56,0) -> 1.8401238 | I36: =IFERROR(HistoricalFS!I6/HistoricalFS!I56,0) -> 2.3177618 | J36: =IFERROR(HistoricalFS!J6/HistoricalFS!J56,0) -> 1.7156758 | ... L36: =IFERROR(HistoricalFS!L6/HistoricalFS!L56,0) -> 1.3702637 | N36: =IFERROR(AVERAGE(C36:L36),0) -> 2.0489097 | O36: =IFERROR(MEDIAN(C36:L36),0) -> 2.0043945
B37: Inventory Turnover | C37: =IFERROR(HistoricalFS!C9/HistoricalFS!C66,0) -> 20.225686 | D37: =IFERROR(HistoricalFS!D9/HistoricalFS!D66,0) -> 13.991151 | E37: =IFERROR(HistoricalFS!E9/HistoricalFS!E66,0) -> 13.689799 | F37: =IFERROR(HistoricalFS!F9/HistoricalFS!F66,0) -> 15.013866 | G37: =IFERROR(HistoricalFS!G9/HistoricalFS!G66,0) -> 20.17567 | H37: =IFERROR(HistoricalFS!H9/HistoricalFS!H66,0) -> 9.24419 | I37: =IFERROR(HistoricalFS!I9/HistoricalFS!I66,0) -> 15.866063 | J37: =IFERROR(HistoricalFS!J9/HistoricalFS!J66,0) -> 7.9629814 | ... L37: =IFERROR(HistoricalFS!L9/HistoricalFS!L66,0) -> 4.0358724 | N37: =IFERROR(AVERAGE(C37:L37),0) -> 12.734928 | O37: =IFERROR(MEDIAN(C37:L37),0) -> 13.840475
B38: Fixed Asset Turnover | C38: =IFERROR(HistoricalFS!C6/HistoricalFS!C59,0) -> 2.6728792 | D38: =IFERROR(HistoricalFS!D6/HistoricalFS!D59,0) -> 3.4034366 | E38: =IFERROR(HistoricalFS!E6/HistoricalFS!E59,0) -> 4.4765153 | F38: =IFERROR(HistoricalFS!F6/HistoricalFS!F59,0) -> 4.1428651 | G38: =IFERROR(HistoricalFS!G6/HistoricalFS!G59,0) -> 3.6481411 | H38: =IFERROR(HistoricalFS!H6/HistoricalFS!H59,0) -> 2.3045749 | I38: =IFERROR(HistoricalFS!I6/HistoricalFS!I59,0) -> 2.2422111 | J38: =IFERROR(HistoricalFS!J6/HistoricalFS!J59,0) -> 1.4614044 | ... L38: =IFERROR(HistoricalFS!L6/HistoricalFS!L59,0) -> 0.87232167 | N38: =IFERROR(AVERAGE(C38:L38),0) -> 2.6491429 | O38: =IFERROR(MEDIAN(C38:L38),0) -> 2.4887271
B39: Capital Turnover Ratio | C39: =IFERROR(HistoricalFS!C6/(SUM(HistoricalFS!C53:C54)+HistoricalFS!C55),0) -> 1.0443423 | D39: =IFERROR(HistoricalFS!D6/(SUM(HistoricalFS!D53:D54)+HistoricalFS!D55),0) -> 1.0977227 | E39: =IFERROR(HistoricalFS!E6/(SUM(HistoricalFS!E53:E54)+HistoricalFS!E55),0) -> 1.5530768 | F39: =IFERROR(HistoricalFS!F6/(SUM(HistoricalFS!F53:F54)+HistoricalFS!F55),0) -> 1.4779933 | G39: =IFERROR(HistoricalFS!G6/(SUM(HistoricalFS!G53:G54)+HistoricalFS!G55),0) -> 1.1842559 | H39: =IFERROR(HistoricalFS!H6/(SUM(HistoricalFS!H53:H54)+HistoricalFS!H55),0) -> 1.0870591 | I39: =IFERROR(HistoricalFS!I6/(SUM(HistoricalFS!I53:I54)+HistoricalFS!I55),0) -> 1.4786936 | J39: =IFERROR(HistoricalFS!J6/(SUM(HistoricalFS!J53:J54)+HistoricalFS!J55),0) -> 0.92369435 | ... L39: =IFERROR(HistoricalFS!L6/(SUM(HistoricalFS!L53:L54)+HistoricalFS!L55),0) -> 0.53569619 | N39: =IFERROR(AVERAGE(C39:L39),0) -> 1.1072972 | O39: =IFERROR(MEDIAN(C39:L39),0) -> 1.0923909
A41: # | B41: WORKING CAPITAL CYCLE (IN DAYS)
B42: Debtor Days | C42: =IFERROR(365/C35,0) -> 127.30289 | D42: =IFERROR(365/D35,0) -> 122.92787 | E42: =IFERROR(365/E35,0) -> 129.32737 | F42: =IFERROR(365/F35,0) -> 110.55761 | G42: =IFERROR(365/G35,0) -> 110.62177 | H42: =IFERROR(365/H35,0) -> 72.096462 | I42: =IFERROR(365/I35,0) -> 35.924566 | J42: =IFERROR(365/J35,0) -> 37.070972 | ... L42: =IFERROR(365/L35,0) -> 45.566995 | N42: =IFERROR(AVERAGE(C42:L42),0) -> 82.725146 | O42: =IFERROR(MEDIAN(C42:L42),0) -> 91.327038
B43: Payable Days | C43: =IFERROR(365/C36,0) -> 126.1842 | D43: =IFERROR(365/D36,0) -> 240.59207 | E43: =IFERROR(365/E36,0) -> 149.48539 | F43: =IFERROR(365/F36,0) -> 147.24602 | G43: =IFERROR(365/G36,0) -> 168.30629 | H43: =IFERROR(365/H36,0) -> 198.35622 | I43: =IFERROR(365/I36,0) -> 157.47952 | J43: =IFERROR(365/J36,0) -> 212.74416 | ... L43: =IFERROR(365/L36,0) -> 266.37209 | N43: =IFERROR(AVERAGE(C43:L43),0) -> 187.57716 | O43: =IFERROR(MEDIAN(C43:L43),0) -> 183.33126
B44: Inventory Days | C44: =IFERROR(365/C37,0) -> 18.04636 | D44: =IFERROR(365/D37,0) -> 26.087919 | E44: =IFERROR(365/E37,0) -> 26.662188 | F44: =IFERROR(365/F37,0) -> 24.31086 | G44: =IFERROR(365/G37,0) -> 18.091096 | H44: =IFERROR(365/H37,0) -> 39.48426 | I44: =IFERROR(365/I37,0) -> 23.005076 | J44: =IFERROR(365/J37,0) -> 45.837103 | ... L44: =IFERROR(365/L37,0) -> 90.438934 | N44: =IFERROR(AVERAGE(C44:L44),0) -> 36.305563 | O44: =IFERROR(MEDIAN(C44:L44),0) -> 26.375053
B45: Cash Conversion Cycle | C45: =IFERROR(SUM(C42,C44)-C43,0) -> 19.165053 | D45: =IFERROR(SUM(D42,D44)-D43,0) -> -91.576277 | E45: =IFERROR(SUM(E42,E44)-E43,0) -> 6.5041725 | F45: =IFERROR(SUM(F42,F44)-F43,0) -> -12.377549 | G45: =IFERROR(SUM(G42,G44)-G43,0) -> -39.593429 | H45: =IFERROR(SUM(H42,H44)-H43,0) -> -86.775496 | I45: =IFERROR(SUM(I42,I44)-I43,0) -> -98.549873 | J45: =IFERROR(SUM(J42,J44)-J43,0) -> -129.83608 | ... L45: =IFERROR(SUM(L42,L44)-L43,0) -> -130.36616 | N45: =IFERROR(AVERAGE(C45:L45),0) -> -68.546448 | O45: =IFERROR(MEDIAN(C45:L45),0) -> -89.175886
A47: # | B47: LEVERAGE & SOLVENCY RATIOS
...

Sheet Common Size Statement
B2: Common Size Statement - ADANI ENTERPRISES LTD
B3: Year | C3: 42825 | D3: 43190 | E3: 43555 | F3: 43921 | G3: 44286 | H3: 44651 | I3: 45016 | J3: 45382 | K3: 45747 | L3: 46112
A4: # | B4: COMMON SIZE INCOME STATEMENT (% OF SALES)
B5: Sales | C5: =IFERROR(HistoricalFS!C6/HistoricalFS!C6,0) -> 1 | D5: =IFERROR(HistoricalFS!D6/HistoricalFS!D6,0) -> 1 | E5: =IFERROR(HistoricalFS!E6/HistoricalFS!E6,0) -> 1 | F5: =IFERROR(HistoricalFS!F6/HistoricalFS!F6,0) -> 1 | G5: =IFERROR(HistoricalFS!G6/HistoricalFS!G6,0) -> 1 | H5: =IFERROR(HistoricalFS!H6/HistoricalFS!H6,0) -> 1 | I5: =IFERROR(HistoricalFS!I6/HistoricalFS!I6,0) -> 1 | J5: =IFERROR(HistoricalFS!J6/HistoricalFS!J6,0) -> 1 | ... L5: =IFERROR(HistoricalFS!L6/HistoricalFS!L6,0) -> 1
B6: COGS | C6: 0.91454132 | D6: 0.91234782 | E6: 0.90482473 | F6: 0.88637813 | G6: 0.89661187 | H6: 0.90394681 | I6: 0.86061354 | J6: 0.78347772 | K6: 0.75073587 | L6: 0.75170941
B7: Gross Profit | C7: 0.08545868 | D7: 0.087652183 | E7: 0.095175273 | F7: 0.11362187 | G7: 0.10338813 | H7: 0.096053194 | I7: 0.13938646 | J7: 0.21652228 | K7: 0.24926413 | L7: 0.24829059
B8: Selling & General Expenses | C8: 0.033389666 | D8: 0.030929253 | E8: 0.046403472 | F8: 0.060758858 | G8: 0.040013527 | H8: 0.042558662 | I8: 0.070249531 | J8: 0.098533431 | K8: 0.1036789 | L8: 0.10903535
B9: EBITDA | C9: 0.052069014 | D9: 0.05672293 | E9: 0.048771802 | F9: 0.052863011 | G9: 0.063374605 | H9: 0.053494531 | I9: 0.069136934 | J9: 0.11798884 | K9: 0.14558523 | L9: 0.13925524
B10: Depreciation | C10: 0.0086349659 | D10: 0.018481279 | E10: 0.0096528711 | F10: 0.010876317 | G10: 0.01358571 | H10: 0.017974312 | I10: 0.019101063 | J10: 0.031550706 | K10: 0.043018957 | L10: 0.061067233
B11: EBIT (Operating Profit) | C11: 0.043434048 | D11: 0.038241651 | E11: 0.039118931 | F11: 0.041986694 | G11: 0.049788895 | H11: 0.035520219 | I11: 0.050035871 | J11: 0.086438138 | K11: 0.10256628 | L11: 0.078188003
B12: Other Income | C12: 0.020513313 | D12: 0.010110534 | E12: 0.012487289 | F12: 0.020098354 | G12: 0.012502425 | H12: 0.014579478 | I12: 0.006540954 | J12: 0.011889425 | K12: 0.065408002 | L12: 0.11633823
B13: Interest | C13: 0.034415866 | D13: 0.034800489 | E13: 0.040245763 | F13: 0.036226435 | G13: 0.034824227 | H13: 0.036385385 | I13: 0.031118987 | J13: 0.047237645 | K13: 0.061065787 | L13: 0.059910454
B14: Earnings Before Tax | C14: 0.029531496 | D14: 0.013551695 | E14: 0.011360456 | F14: 0.025858613 | G14: 0.027467092 | H14: 0.013714312 | I14: 0.025457839 | J14: 0.051089918 | K14: 0.10690849 | L14: 0.13461578
B15: Tax | C15: 0.0074220852 | D15: 0.0031207619 | E15: 0.0035796136 | F15: 0.0074726007 | G15: 0.008590659 | H15: 0.0068665912 | I15: 0.0081381846 | J15: 0.016920695 | K15: 0.030323587 | L15: 0.038132806
B16: Net Profit | C16: 0.022109411 | D16: 0.010430933 | E16: 0.0077808427 | F16: 0.018386012 | G16: 0.018876433 | H16: 0.0068477206 | I16: 0.017319654 | J16: 0.034169223 | K16: 0.076584904 | L16: 0.096482971
A18: # | B18: COMMON SIZE BALANCE SHEET - EQUITY & LIABILITIES (% OF TOTAL LIABILITIES)
B19: Equity Share Capital | C19: =IFERROR(HistoricalFS!C53/HistoricalFS!C57,0) -> 0.0023099476 | D19: =IFERROR(HistoricalFS!D53/HistoricalFS!D57,0) -> 0.0019498154 | E19: =IFERROR(HistoricalFS!E53/HistoricalFS!E57,0) -> 0.0025855636 | F19: =IFERROR(HistoricalFS!F53/HistoricalFS!F57,0) -> 0.002346237 | G19: =IFERROR(HistoricalFS!G53/HistoricalFS!G57,0) -> 0.0021307049 | H19: =IFERROR(HistoricalFS!H53/HistoricalFS!H57,0) -> 0.0010826257 | I19: =IFERROR(HistoricalFS!I53/HistoricalFS!I57,0) -> 0.00080691695 | J19: =IFERROR(HistoricalFS!J53/HistoricalFS!J57,0) -> 0.00070989893 | ... L19: =IFERROR(HistoricalFS!L53/HistoricalFS!L57,0) -> 0.00049542225
B20: Reserves | C20: =IFERROR(HistoricalFS!C54/HistoricalFS!C57,0) -> 0.29459267 | D20: =IFERROR(HistoricalFS!D54/HistoricalFS!D57,0) -> 0.26556333 | E20: =IFERROR(HistoricalFS!E54/HistoricalFS!E57,0) -> 0.34431771 | F20: =IFERROR(HistoricalFS!F54/HistoricalFS!F57,0) -> 0.35918013 | G20: =IFERROR(HistoricalFS!G54/HistoricalFS!G57,0) -> 0.33029201 | H20: =IFERROR(HistoricalFS!H54/HistoricalFS!H57,0) -> 0.21800693 | I20: =IFERROR(HistoricalFS!I54/HistoricalFS!I57,0) -> 0.23313536 | J20: =IFERROR(HistoricalFS!J54/HistoricalFS!J57,0) -> 0.24262409 | ... L20: =IFERROR(HistoricalFS!L54/HistoricalFS!L57,0) -> 0.30972213
B21: Borrowings | C21: =IFERROR(HistoricalFS!C55/HistoricalFS!C57,0) -> 0.43782979 | D21: =IFERROR(HistoricalFS!D55/HistoricalFS!D57,0) -> 0.31267766 | E21: =IFERROR(HistoricalFS!E55/HistoricalFS!E57,0) -> 0.26432087 | F21: =IFERROR(HistoricalFS!F55/HistoricalFS!F57,0) -> 0.26494473 | G21: =IFERROR(HistoricalFS!G55/HistoricalFS!G57,0) -> 0.31437604 | H21: =IFERROR(HistoricalFS!H55/HistoricalFS!H57,0) -> 0.40954347 | I21: =IFERROR(HistoricalFS!I55/HistoricalFS!I57,0) -> 0.3765645 | J21: =IFERROR(HistoricalFS!J55/HistoricalFS!J57,0) -> 0.40669829 | ... L21: =IFERROR(HistoricalFS!L55/HistoricalFS!L57,0) -> 0.40871872
B22: Other Liabilities | C22: =IFERROR(HistoricalFS!C56/HistoricalFS!C57,0) -> 0.26526759 | D22: =IFERROR(HistoricalFS!D56/HistoricalFS!D57,0) -> 0.41980919 | E22: =IFERROR(HistoricalFS!E56/HistoricalFS!E57,0) -> 0.38877586 | F22: =IFERROR(HistoricalFS!F56/HistoricalFS!F57,0) -> 0.37352891 | G22: =IFERROR(HistoricalFS!G56/HistoricalFS!G57,0) -> 0.35320125 | H22: =IFERROR(HistoricalFS!H56/HistoricalFS!H57,0) -> 0.37136698 | I22: =IFERROR(HistoricalFS!I56/HistoricalFS!I57,0) -> 0.38949322 | J22: =IFERROR(HistoricalFS!J56/HistoricalFS!J57,0) -> 0.34996772 | ... L22: =IFERROR(HistoricalFS!L56/HistoricalFS!L57,0) -> 0.28106373
B23: Total Equity & Liabilities | C23: =IFERROR(HistoricalFS!C57/HistoricalFS!C57,0) -> 1 | D23: =IFERROR(HistoricalFS!D57/HistoricalFS!D57,0) -> 1 | E23: =IFERROR(HistoricalFS!E57/HistoricalFS!E57,0) -> 1 | F23: =IFERROR(HistoricalFS!F57/HistoricalFS!F57,0) -> 1 | G23: =IFERROR(HistoricalFS!G57/HistoricalFS!G57,0) -> 1 | H23: =IFERROR(HistoricalFS!H57/HistoricalFS!H57,0) -> 1 | I23: =IFERROR(HistoricalFS!I57/HistoricalFS!I57,0) -> 1 | J23: =IFERROR(HistoricalFS!J57/HistoricalFS!J57,0) -> 1 | ... L23: =IFERROR(HistoricalFS!L57/HistoricalFS!L57,0) -> 1
A25: # | B25: COMMON SIZE BALANCE SHEET - ASSETS (% OF TOTAL ASSETS)
B26: Net Block | C26: =IFERROR(HistoricalFS!C59/HistoricalFS!C70,0) -> 0.28707326 | D26: =IFERROR(HistoricalFS!D59/HistoricalFS!D70,0) -> 0.18713104 | E26: =IFERROR(HistoricalFS!E59/HistoricalFS!E70,0) -> 0.21205736 | F26: =IFERROR(HistoricalFS!F59/HistoricalFS!F70,0) -> 0.22349753 | G26: =IFERROR(HistoricalFS!G59/HistoricalFS!G70,0) -> 0.20996317 | H26: =IFERROR(HistoricalFS!H59/HistoricalFS!H70,0) -> 0.29652377 | I26: =IFERROR(HistoricalFS!I59/HistoricalFS!I70,0) -> 0.40261709 | J26: =IFERROR(HistoricalFS!J59/HistoricalFS!J70,0) -> 0.41085899 | ... L26: =IFERROR(HistoricalFS!L59/HistoricalFS!L70,0) -> 0.44150161
B27: Capital Work in Progress | C27: =IFERROR(HistoricalFS!C60/HistoricalFS!C70,0) -> 0.16238713 | D27: =IFERROR(HistoricalFS!D60/HistoricalFS!D70,0) -> 0.097967143 | E27: =IFERROR(HistoricalFS!E60/HistoricalFS!E70,0) -> 0.1355298 | F27: =IFERROR(HistoricalFS!F60/HistoricalFS!F70,0) -> 0.15673004 | G27: =IFERROR(HistoricalFS!G60/HistoricalFS!G70,0) -> 0.17098064 | H27: =IFERROR(HistoricalFS!H60/HistoricalFS!H70,0) -> 0.23176753 | I27: =IFERROR(HistoricalFS!I60/HistoricalFS!I70,0) -> 0.17005569 | J27: =IFERROR(HistoricalFS!J60/HistoricalFS!J70,0) -> 0.21906921 | ... L27: =IFERROR(HistoricalFS!L60/HistoricalFS!L70,0) -> 0.19838901
B28: Investments | C28: =IFERROR(HistoricalFS!C61/HistoricalFS!C70,0) -> 0.021880232 | D28: =IFERROR(HistoricalFS!D61/HistoricalFS!D70,0) -> 0.025896839 | E28: =IFERROR(HistoricalFS!E61/HistoricalFS!E70,0) -> 0.035530929 | F28: =IFERROR(HistoricalFS!F61/HistoricalFS!F70,0) -> 0.041653067 | G28: =IFERROR(HistoricalFS!G61/HistoricalFS!G70,0) -> 0.10661158 | H28: =IFERROR(HistoricalFS!H61/HistoricalFS!H70,0) -> 0.042251834 | I28: =IFERROR(HistoricalFS!I61/HistoricalFS!I70,0) -> 0.044664764 | J28: =IFERROR(HistoricalFS!J61/HistoricalFS!J70,0) -> 0.054180794 | ... L28: =IFERROR(HistoricalFS!L61/HistoricalFS!L70,0) -> 0.036142249
B29: Other Assets | C29: =IFERROR(HistoricalFS!C62/HistoricalFS!C70,0) -> 0.190322 | D29: =IFERROR(HistoricalFS!D62/HistoricalFS!D70,0) -> 0.39957174 | E29: =IFERROR(HistoricalFS!E62/HistoricalFS!E70,0) -> 0.17760575 | F29: =IFERROR(HistoricalFS!F62/HistoricalFS!F70,0) -> 0.17096085 | G29: =IFERROR(HistoricalFS!G62/HistoricalFS!G70,0) -> 0.21117576 | H29: =IFERROR(HistoricalFS!H62/HistoricalFS!H70,0) -> 0.18910639 | I29: =IFERROR(HistoricalFS!I62/HistoricalFS!I70,0) -> 0.2068068 | J29: =IFERROR(HistoricalFS!J62/HistoricalFS!J70,0) -> 0.1518155 | ... L29: =IFERROR(HistoricalFS!L62/HistoricalFS!L70,0) -> 0.15888384
B30: Total Non Current Assets | C30: =IFERROR(HistoricalFS!C63/HistoricalFS!C70,0) -> 0.66166262 | D30: =IFERROR(HistoricalFS!D63/HistoricalFS!D70,0) -> 0.71056677 | E30: =IFERROR(HistoricalFS!E63/HistoricalFS!E70,0) -> 0.56072384 | F30: =IFERROR(HistoricalFS!F63/HistoricalFS!F70,0) -> 0.59284148 | G30: =IFERROR(HistoricalFS!G63/HistoricalFS!G70,0) -> 0.69873115 | H30: =IFERROR(HistoricalFS!H63/HistoricalFS!H70,0) -> 0.75964952 | I30: =IFERROR(HistoricalFS!I63/HistoricalFS!I70,0) -> 0.82414434 | J30: =IFERROR(HistoricalFS!J63/HistoricalFS!J70,0) -> 0.83592449 | ... L30: =IFERROR(HistoricalFS!L63/HistoricalFS!L70,0) -> 0.83491671
B31: Receivables | C31: =IFERROR(HistoricalFS!C65/HistoricalFS!C70,0) -> 0.26761934 | D31: =IFERROR(HistoricalFS!D65/HistoricalFS!D70,0) -> 0.21449689 | E31: =IFERROR(HistoricalFS!E65/HistoricalFS!E70,0) -> 0.33634967 | F31: =IFERROR(HistoricalFS!F65/HistoricalFS!F70,0) -> 0.28045895 | G31: =IFERROR(HistoricalFS!G65/HistoricalFS!G70,0) -> 0.23214668 | H31: =IFERROR(HistoricalFS!H65/HistoricalFS!H70,0) -> 0.13498062 | I31: =IFERROR(HistoricalFS!I65/HistoricalFS!I70,0) -> 0.088852032 | J31: =IFERROR(HistoricalFS!J65/HistoricalFS!J70,0) -> 0.060982373 | ... L31: =IFERROR(HistoricalFS!L65/HistoricalFS!L70,0) -> 0.048080223
B32: Inventory | C32: =IFERROR(HistoricalFS!C66/HistoricalFS!C70,0) -> 0.034695421 | D32: =IFERROR(HistoricalFS!D66/HistoricalFS!D70,0) -> 0.04153082 | E32: =IFERROR(HistoricalFS!E66/HistoricalFS!E70,0) -> 0.062742353 | F32: =IFERROR(HistoricalFS!F66/HistoricalFS!F70,0) -> 0.054663823 | G32: =IFERROR(HistoricalFS!G66/HistoricalFS!G70,0) -> 0.034040133 | H32: =IFERROR(HistoricalFS!H66/HistoricalFS!H70,0) -> 0.066822751 | I32: =IFERROR(HistoricalFS!I66/HistoricalFS!I70,0) -> 0.048967472 | J32: =IFERROR(HistoricalFS!J66/HistoricalFS!J70,0) -> 0.059076419 | ... L32: =IFERROR(HistoricalFS!L66/HistoricalFS!L70,0) -> 0.071733416
B33: Cash & Bank | C33: =IFERROR(HistoricalFS!C67/HistoricalFS!C70,0) -> 0.036022622 | D33: =IFERROR(HistoricalFS!D67/HistoricalFS!D70,0) -> 0.033405525 | E33: =IFERROR(HistoricalFS!E67/HistoricalFS!E70,0) -> 0.040184144 | F33: =IFERROR(HistoricalFS!F67/HistoricalFS!F70,0) -> 0.072035748 | G33: =IFERROR(HistoricalFS!G67/HistoricalFS!G70,0) -> 0.035082043 | H33: =IFERROR(HistoricalFS!H67/HistoricalFS!H70,0) -> 0.038547104 | I33: =IFERROR(HistoricalFS!I67/HistoricalFS!I70,0) -> 0.038036154 | J33: =IFERROR(HistoricalFS!J67/HistoricalFS!J70,0) -> 0.044016723 | ... L33: =IFERROR(HistoricalFS!L67/HistoricalFS!L70,0) -> 0.045269649
B34: Total Current Assets | C34: =IFERROR(HistoricalFS!C68/HistoricalFS!C70,0) -> 0.33833738 | D34: =IFERROR(HistoricalFS!D68/HistoricalFS!D70,0) -> 0.28943323 | E34: =IFERROR(HistoricalFS!E68/HistoricalFS!E70,0) -> 0.43927616 | F34: =IFERROR(HistoricalFS!F68/HistoricalFS!F70,0) -> 0.40715852 | G34: =IFERROR(HistoricalFS!G68/HistoricalFS!G70,0) -> 0.30126885 | H34: =IFERROR(HistoricalFS!H68/HistoricalFS!H70,0) -> 0.24035048 | I34: =IFERROR(HistoricalFS!I68/HistoricalFS!I70,0) -> 0.17585566 | J34: =IFERROR(HistoricalFS!J68/HistoricalFS!J70,0) -> 0.16407551 | ... L34: =IFERROR(HistoricalFS!L68/HistoricalFS!L70,0) -> 0.16508329
B35: Total Assets | C35: =IFERROR(HistoricalFS!C70/HistoricalFS!C70,0) -> 1 | D35: =IFERROR(HistoricalFS!D70/HistoricalFS!D70,0) -> 1 | E35: =IFERROR(HistoricalFS!E70/HistoricalFS!E70,0) -> 1 | F35: =IFERROR(HistoricalFS!F70/HistoricalFS!F70,0) -> 1 | G35: =IFERROR(HistoricalFS!G70/HistoricalFS!G70,0) -> 1 | H35: =IFERROR(HistoricalFS!H70/HistoricalFS!H70,0) -> 1 | I35: =IFERROR(HistoricalFS!I70/HistoricalFS!I70,0) -> 1 | J35: =IFERROR(HistoricalFS!J70/HistoricalFS!J70,0) -> 1 | ... L35: =IFERROR(HistoricalFS!L70/HistoricalFS!L70,0) -> 1

Sheet Data Sheet
A1: COMPANY NAME | B1: ADANI ENTERPRISES LTD | E1: =IF(B2<>B3, "A NEW VERSION OF THE WORKSHEET IS AVAILABLE", "")
A2: LATEST VERSION | B2: 2.1 | E2: PLEASE DO NOT MAKE ANY CHANGES TO THIS SHEET
A3: CURRENT VERSION | B3: 2.1
A5: META
A6: Number of shares | B6: =IF(B9>0, B9/B8, 0) -> 135.30373
A7: Face Value | B7: 1
A8: Current Price | B8: 3009.5
A9: Market Capitalization | B9: 407196.58
A15: PROFIT & LOSS
A16: Report Date | B16: 42825 | C16: 43190 | D16: 43555 | E16: 43921 | F16: 44286 | G16: 44651 | H16: 45016 | I16: 45382 | J16: 45747 | K16: 46112
A17: Sales | B17: 36532.86 | C17: 35923.92 | D17: 40378.66 | E17: 43402.56 | F17: 39537.13 | G17: 69420.18 | H17: 127539.5 | I17: 96420.98 | J17: 97894.75 | K17: 100468.61
A18: Raw Material Cost | B18: 30945.16 | C18: 30771.08 | D18: 33821.4 | E18: 34350.2 | F18: 29791.08 | G18: 57651.32 | H18: 93814.06 | I18: 51507.72 | J18: 49524.73 | K18: 56933.41
A19: Change in Inventory | B19: -36.38 | C19: 772.74 | D19: 499.99 | E19: -310.13 | F19: -456.74 | G19: 3933.82 | H19: 327.16 | I19: 1116.49 | J19: -1844.54 | K19: 2824.59
A20: Power and Fuel | B20: 7.42 | C20: 2.91 | D20: 5.74 | E20: 12.22 | F20: 13.4 | G20: 58.98 | H20: 18.42 | I20: 26.46 | J20: 2037.48 | K20: 2142.7
A21: Other Mfr. Exp | B21: 1910.37 | C21: 2204.89 | D21: 2551.28 | E21: 3115.25 | F21: 4357.88 | G21: 7793.57 | H21: 14377.83 | I21: 22793.04 | J21: 16964.51 | K21: 15610.12
A22: Employee Cost | B22: 511.48 | C22: 568.97 | D22: 657.18 | E22: 683.28 | F22: 830.36 | G22: 1182.1 | H22: 1879.07 | I22: 2332.96 | J22: 3121.84 | K22: 3661.56
A23: Selling and admin | B23: 1004.69 | C23: 928.28 | D23: 1230.62 | E23: 1954.57 | F23: 1306.48 | G23: 2412.38 | H23: 8135.29 | I23: 8272.86 | J23: 9245.98 | K23: 9817.24
A24: Other Expenses | B24: 215.13 | C24: 182.82 | D24: 643.09 | E24: 682.52 | F24: 275.54 | G24: 542.05 | H24: 824.3 | I24: 1227.83 | J24: 903.64 | K24: 1137.39
A25: Other Income | B25: 749.41 | C25: 363.21 | D25: 504.22 | E25: 872.32 | F25: 494.31 | G25: 1012.11 | H25: 834.23 | I25: 1146.39 | J25: 6403.1 | K25: 11688.34
A26: Depreciation | B26: 315.46 | C26: 663.92 | D26: 389.77 | E26: 472.06 | F26: 537.14 | G26: 1247.78 | H26: 2436.14 | I26: 3042.15 | J26: 4211.33 | K26: 6135.34
A27: Interest | B27: 1257.31 | C27: 1250.17 | D27: 1625.07 | E27: 1572.32 | F27: 1376.85 | G27: 2525.88 | H27: 3968.9 | I27: 4554.7 | J27: 5978.02 | K27: 6019.12
... A31: Dividend Amount | B31: 43.99 | C31: 43.99 | D31: 43.99 | E31: 109.98 | F31: 109.98 | G31: 109.98 | H31: 136.8 | I31: 148.2 | J31: 150.05 | K31: 168.01
A40: Quarters
A41: Report Date | B41: 45382 | C41: 45473 | D41: 45565 | E41: 45657 | F41: 45747 | G41: 45838 | H41: 45930 | I41: 46022 | J41: 46112 | K41: 46203
A42: Sales | B42: 29180.02 | C42: 25472.4 | D42: 22608.07 | E42: 22848.42 | F42: 26965.86 | G42: 21961.2 | H42: 21248.51 | I42: 24819.59 | J42: 32439.31 | K42: 32923.98
A43: Expenses | B43: 25984.58 | C43: 21766.59 | D43: 18842.27 | E43: 19778.01 | F43: 23255.85 | G43: 18650.91 | H43: 17941.95 | I43: 21178.07 | J43: 28708.56 | K43: 27904.69
A44: Other Income | B44: -175.65 | C44: 590.56 | D44: 582.57 | E44: 648.46 | F44: 4581.51 | G44: 475.42 | H44: 4178.84 | I44: 6287.94 | J44: 747.8 | K44: -2021.74
A45: Depreciation | B45: 811.47 | C45: 934.08 | D45: 1035.19 | E45: 1005.65 | F45: 1236.41 | G45: 1283.95 | H45: 1376.55 | I45: 1371.59 | J45: 2103.25 | K45: 1926
A46: Interest | B46: 1512.62 | C46: 1130.49 | D46: 909.83 | E46: 2141.32 | F46: 1796.38 | G46: 1035.48 | H46: 1711.22 | I46: 1625.94 | J46: 1646.48 | K46: 2420.93
A47: Profit before tax | B47: 695.7 | C47: 2231.8 | D47: 2403.35 | E47: 571.9 | F47: 5258.73 | G47: 1466.28 | H47: 4397.63 | I47: 6931.93 | J47: 728.82 | K47: -1349.38
A48: Tax | B48: 430.12 | C48: 583.6 | D48: 512.37 | E48: 588.44 | F48: 1284.11 | G48: 571.25 | H48: 1001.07 | I48: 1405.11 | J48: 853.72 | K48: 219.04
A49: Net profit | B49: 450.58 | C49: 1454.5 | D49: 1741.75 | E49: 57.83 | F49: 3844.91 | G49: 885.23 | H49: 3198.75 | I49: 5627.02 | J49: -104.93 | K49: -1160.23
A50: Operating Profit | B50: 3195.44 | C50: 3705.81 | D50: 3765.8 | E50: 3070.41 | F50: 3710.01 | G50: 3310.29 | H50: 3306.56 | I50: 3641.52 | J50: 3730.75 | K50: 5019.29
A55: BALANCE SHEET
A56: Report Date | B56: 42825 | C56: 43190 | D56: 43555 | E56: 43921 | F56: 44286 | G56: 44651 | H56: 45016 | I56: 45382 | J56: 45747 | K56: 46112
A57: Equity Share Capital | B57: 109.98 | C57: 109.98 | D57: 109.98 | E57: 109.98 | F57: 109.98 | G57: 109.98 | H57: 114 | I57: 114 | J57: 115.42 | K57: 129.24
A58: Reserves | B58: 14025.99 | C58: 14979.19 | D58: 14645.96 | E58: 16836.59 | F58: 17048.59 | G58: 22146.53 | H58: 32937.01 | I58: 38962.09 | J58: 50198.55 | K58: 80796.71
A59: Borrowings | B59: 20845.72 | C59: 17636.69 | D59: 11243.2 | E59: 12419.3 | F59: 16227.06 | G59: 41604.03 | H59: 53200.46 | I59: 65310.15 | J59: 91472.6 | K59: 106621.79
A60: Other Liabilities | B60: 12629.78 | C60: 23679.48 | D60: 16537.04 | E60: 17509.19 | F60: 18231.09 | G60: 37725.82 | H60: 55027.01 | I60: 56200 | J60: 56056.31 | K60: 73320.64
A61: Total | B61: 47611.47 | C61: 56405.34 | D61: 42536.18 | E61: 46875.06 | F61: 51616.72 | G61: 101586.36 | H61: 141278.48 | I61: 160586.24 | J61: 197842.88 | K61: 260868.38
...
